<?xml version="1.0"?>

<robot name="test_robot">
    <link name="body_link">
        <visual>
            <origin xyz="0.0 0.0 0.0" rpy="0.0 0.0 0.0"/>
            <geometry>
                <sphere radius="0.2"/>
            </geometry>
            <material name="grey">
                <color rgba="0.4 0.4 0.4 1.0"/>
            </material>
        </visual>
        <collision>
            <origin xyz="0.0 0.0 0.0" rpy="0.0 0.0 0.0"/>
            <geometry>
                <sphere radius="0.2"/>
            </geometry>
        </collision>
    </link>

    <joint name="leg_joint1" type="revolute">
        <origin xyz="0.0 0.0 0.0" rpy="0.0 0.0 0.0"/>
        <axis xyz="0 1 0"/>
        <limit lower="-2.96705972839" upper="2.96705972839" effort="204" velocity="1.91986217719"/>
        <dynamics damping='0.1'/>
        <parent link="body_link"/>
        <child link="leg_link1"/>
    </joint>

    <link name="leg_link1">
        <visual>
            <origin xyz="0.0 0.0 -0.5" rpy="0.0 0.0 0.0"/>
            <geometry>
                <cylinder radius="0.1" length="1.0"/>
            </geometry>
            <material name="red">
                <color rgba="0.4 0.1 0.1 1.0"/>
            </material>
        </visual>
        <collision>
            <origin xyz="0.0 0.0 -0.5" rpy="0.0 0.0 0.0"/>
            <geometry>
                <cylinder radius="0.1" length="1.0"/>
            </geometry>
        </collision>
    </link>

    <joint name="leg_joint2" type="revolute">
        <origin xyz="0.0 0.0 0.0" rpy="0.0 0.0 0.0"/>
        <axis xyz="0 0 1"/>
        <limit lower="-2.96705972839" upper="2.96705972839" effort="204" velocity="1.91986217719"/>
        <dynamics damping='0.1"'/>
        <parent link="body_link"/>
        <child link="leg_link2"/>
    </joint>

    <link name="leg_link2">
        <visual>
            <origin xyz="0.5 0.0 0.0" rpy="0.0 1.57 0.0"/>
            <geometry>
                <cylinder radius="0.1" length="1.0"/>
            </geometry>
            <material name="green">
                <color rgba="0.1 0.4 0.1 1.0"/>
            </material>
        </visual>
        <collision>
            <origin xyz="0.5 0.0 0.0" rpy="0.0 1.57 0.0"/>
            <geometry>
                <cylinder radius="0.1" length="1.0"/>
            </geometry>
        </collision>
    </link>

    <joint name="leg_joint3" type="revolute">
        <origin xyz="0.0 0.0 0.0" rpy="0.0 0.0 0.0"/>
        <axis xyz="1 0 0"/>
        <limit lower="-2.96705972839" upper="2.96705972839" effort="204" velocity="1.91986217719"/>
        <dynamics damping='0.1'/>
        <parent link="body_link"/>
        <child link="leg_link3"/>
    </joint>

    <link name="leg_link3">
        <visual>
            <origin xyz="0.0 0.5 0.0" rpy="1.57 0.0 0.0"/>
            <geometry>
                <cylinder radius="0.1" length="1.0"/>
            </geometry>
            <material name="blue">
                <color rgba="0.1 0.1 0.4 1.0"/>
            </material>
        </visual>
        <collision>
            <origin xyz="0.0 0.5 0.0" rpy="1.57 0.0 0.0"/>
            <geometry>
                <cylinder radius="0.1" length="1.0"/>
            </geometry>
        </collision>
    </link>
</robot>

